Workbook

Sheet Assumptions & WACC
B2: Oracle Corporation (ORCL) — DCF Valuation Model
B3: Fiscal Year End: May 31 | All dollar figures in $ millions unless noted | Model updated Oct 5, 2026
B5: MARKET DATA
B6: Current Share Price ($) | C6: 142.48
B7: Diluted Shares Outstanding (mm) | C7: 2880
B8: Market Capitalization ($mm) | C8: =C6*C7 -> 410342.4
B10: CAPITAL STRUCTURE (Book Value, $mm)
B11: Total Debt (ST + LT notes payable) | C11: 129541
B12: Cash & Cash Equivalents | C12: 31289
B13: Net Debt (incl. lease liabilities) | C13: =C11-C12+C35 -> 98252
B15: WACC ASSUMPTIONS
B16: Risk-Free Rate (10-Yr US Treasury) | C16: 0.053
B17: Equity Risk Premium | C17: 0.042
B18: Levered Beta | C18: 1.73
B19: Cost of Equity (CAPM) | C19: =C16+C18*C17 -> 0.12566
B20: Pre-Tax Cost of Debt | C20: 0.06
B21: Tax Rate | C21: 0.19
B22: After-Tax Cost of Debt | C22: =C20*(1-C21) -> 0.0486
B23: Weight of Equity | C23: =C8/(C8+C11) -> 0.76005745
B24: Weight of Debt | C24: =C11/(C8+C11) -> 0.23994255
B25: WACC | C25: =C23*C19+C24*C22 -> 0.10717003
B27: MODEL SETTINGS
B28: Active Scenario (1 = Bear, 2 = Base, 3 = Bull) | C28: 2
B29: Scenario in use | C29: =CHOOSE(C28,"Bear","Base","Bull") -> Base
B30: Mid-Year Convention (1 = On, 0 = Off) | C30: 1
B31: Terminal Growth Rate | C31: 0.035
B32: ΔNWC (% of incremental revenue) | C32: 0.03
B33: Net PP&E, end of FY2026 ($mm) | C33: 130000
B34: Depreciation Rate (% of beginning net PP&E) | C34: 0.12
B35: Operating Lease Liabilities ($mm) — excluded, see note | C35: 0
B37: OPERATING ASSUMPTIONS — LIVE (driven by active scenario; do not edit black cells)
C38: FY2026A | D38: FY2027E | E38: FY2028E | F38: FY2029E | G38: FY2030E | H38: FY2031E | I38: FY2032E | J38: FY2033E | K38: FY2034E | L38: FY2035E | M38: FY2036E
B39: Revenue Growth % | C39: n/a | D39: =CHOOSE($C$28,D47,D50,D53) -> 0.326 | E39: =CHOOSE($C$28,E47,E50,E53) -> 0.463 | F39: =CHOOSE($C$28,F47,F50,F53) -> 0.25 | G39: =CHOOSE($C$28,G47,G50,G53) -> 0.18 | H39: =CHOOSE($C$28,H47,H50,H53) -> 0.12 | I39: =CHOOSE($C$28,I47,I50,I53) -> 0.103 | J39: =CHOOSE($C$28,J47,J50,J53) -> 0.086 | K39: =CHOOSE($C$28,K47,K50,K53) -> 0.069 | ... M39: =CHOOSE($C$28,M47,M50,M53) -> 0.035
B40: EBITDA Margin % | C40: 0.45 | D40: =CHOOSE($C$28,D48,D51,D54) -> 0.455 | E40: =CHOOSE($C$28,E48,E51,E54) -> 0.46 | F40: =CHOOSE($C$28,F48,F51,F54) -> 0.46 | G40: =CHOOSE($C$28,G48,G51,G54) -> 0.46 | H40: =CHOOSE($C$28,H48,H51,H54) -> 0.46 | I40: =CHOOSE($C$28,I48,I51,I54) -> 0.46 | J40: =CHOOSE($C$28,J48,J51,J54) -> 0.46 | K40: =CHOOSE($C$28,K48,K51,K54) -> 0.46 | ... M40: =CHOOSE($C$28,M48,M51,M54) -> 0.46
B41: Capex % of Revenue | C41: 0.826 | D41: 0.65 | E41: 0.5 | F41: 0.35 | G41: 0.25 | H41: 0.18 | I41: 0.16 | J41: 0.15 | K41: 0.14 | L41: 0.13 | M41: 0.125
B42: D&A % of Revenue (memo) | C42: 0.144 | D42: ='DCF Valuation'!D17/'DCF Valuation'!D7 -> 0.17455053 | E42: ='DCF Valuation'!E17/'DCF Valuation'!E7 -> 0.15830791 | F42: ='DCF Valuation'!F17/'DCF Valuation'!F7 -> 0.15944877 | G42: ='DCF Valuation'!G17/'DCF Valuation'!G7 -> 0.15450417 | H42: ='DCF Valuation'!H17/'DCF Valuation'!H7 -> 0.14818184 | I42: ='DCF Valuation'!I17/'DCF Valuation'!I7 -> 0.137806 | J42: ='DCF Valuation'!J17/'DCF Valuation'!J7 -> 0.12934557 | K42: ='DCF Valuation'!K17/'DCF Valuation'!K7 -> 0.12331534 | ... M42: ='DCF Valuation'!M17/'DCF Valuation'!M7 -> 0.11635587
B45: SCENARIO INPUTS (FY27-FY31 are inputs; FY32-FY36 growth fades linearly to terminal growth)
C46: FY2026A | D46: FY2027E | E46: FY2028E | F46: FY2029E | G46: FY2030E | H46: FY2031E | I46: FY2032E | J46: FY2033E | K46: FY2034E | L46: FY2035E | M46: FY2036E
B47: Bear: Revenue Growth % | C47: n/a | D47: 0.25 | E47: 0.3 | F47: 0.15 | G47: 0.1 | H47: 0.07 | I47: =H47-($H47-$C$31)/5 -> 0.063 | J47: =I47-($H47-$C$31)/5 -> 0.056 | K47: =J47-($H47-$C$31)/5 -> 0.049 | L47: =K47-($H47-$C$31)/5 -> 0.042 | M47: =L47-($H47-$C$31)/5 -> 0.035
B48: Bear: EBITDA Margin % | C48: n/a | D48: 0.44 | E48: 0.43 | F48: 0.42 | G48: 0.41 | H48: 0.4 | I48: =H48 -> 0.4 | J48: =I48 -> 0.4 | K48: =J48 -> 0.4 | L48: =K48 -> 0.4 | M48: =L48 -> 0.4
...

Sheet DCF Valuation
B2: Oracle Corporation (ORCL) — Unlevered Free Cash Flow & Valuation
B3: $ in millions except per-share data | 10-year forecast, EBITDA-based build | J3: Scenario: | K3: ='Assumptions & WACC'!$C$29 -> Base | L3: Mid-year: | M3: =IF('Assumptions & WACC'!$C$30=1,"On","Off") -> On
B5: UNLEVERED FREE CASH FLOW BUILD
C6: FY2026A | D6: FY2027E | E6: FY2028E | F6: FY2029E | G6: FY2030E | H6: FY2031E | I6: FY2032E | J6: FY2033E | K6: FY2034E | L6: FY2035E | M6: FY2036E
B7: Revenue | C7: 67400 | D7: =C7*(1+'Assumptions & WACC'!D39) -> 89372.4 | E7: =D7*(1+'Assumptions & WACC'!E39) -> 130751.82 | F7: =E7*(1+'Assumptions & WACC'!F39) -> 163439.78 | G7: =F7*(1+'Assumptions & WACC'!G39) -> 192858.94 | H7: =G7*(1+'Assumptions & WACC'!H39) -> 216002.01 | I7: =H7*(1+'Assumptions & WACC'!I39) -> 238250.22 | J7: =I7*(1+'Assumptions & WACC'!J39) -> 258739.73 | K7: =J7*(1+'Assumptions & WACC'!K39) -> 276592.78 | ... M7: =L7*(1+'Assumptions & WACC'!M39) -> 301159.75
B8: Revenue Growth % | C8: n/a | D8: =D7/C7-1 -> 0.326 | E8: =E7/D7-1 -> 0.463 | F8: =F7/E7-1 -> 0.25 | G8: =G7/F7-1 -> 0.18 | H8: =H7/G7-1 -> 0.12 | I8: =I7/H7-1 -> 0.103 | J8: =J7/I7-1 -> 0.086 | K8: =K7/J7-1 -> 0.069 | ... M8: =M7/L7-1 -> 0.035
B10: EBITDA | C10: =C7*'Assumptions & WACC'!C40 -> 30330 | D10: =D7*'Assumptions & WACC'!D40 -> 40664.442 | E10: =E7*'Assumptions & WACC'!E40 -> 60145.838 | F10: =F7*'Assumptions & WACC'!F40 -> 75182.297 | G10: =G7*'Assumptions & WACC'!G40 -> 88715.111 | H10: =H7*'Assumptions & WACC'!H40 -> 99360.924 | I10: =I7*'Assumptions & WACC'!I40 -> 109595.1 | J10: =J7*'Assumptions & WACC'!J40 -> 119020.28 | ... M10: =M7*'Assumptions & WACC'!M40 -> 138533.48
B11: EBITDA Margin % | C11: =C10/C7 -> 0.45 | D11: =D10/D7 -> 0.455 | E11: =E10/E7 -> 0.46 | F11: =F10/F7 -> 0.46 | G11: =G10/G7 -> 0.46 | H11: =H10/H7 -> 0.46 | I11: =I10/I7 -> 0.46 | J11: =J10/J7 -> 0.46 | ... M11: =M10/M7 -> 0.46
B12: Less: D&A | C12: =-C7*'Assumptions & WACC'!C42 -> -9705.6 | D12: =-'Assumptions & WACC'!$C$34*D23 -> -15600 | E12: =-'Assumptions & WACC'!$C$34*E23 -> -20699.047 | F12: =-'Assumptions & WACC'!$C$34*F23 -> -26060.271 | G12: =-'Assumptions & WACC'!$C$34*G23 -> -29797.509 | H12: =-'Assumptions & WACC'!$C$34*H23 -> -32007.576 | I12: =-'Assumptions & WACC'!$C$34*I23 -> -32832.31 | J12: =-'Assumptions & WACC'!$C$34*J23 -> -33466.837 | K12: =-'Assumptions & WACC'!$C$34*K23 -> -34108.132 | ... M12: =-'Assumptions & WACC'!$C$34*M23 -> -35041.704
B13: EBIT | C13: =C10+C12 -> 20624.4 | D13: =D10+D12 -> 25064.442 | E13: =E10+E12 -> 39446.791 | F13: =F10+F12 -> 49122.026 | G13: =G10+G12 -> 58917.602 | H13: =H10+H12 -> 67353.348 | I13: =I10+I12 -> 76762.789 | J13: =J10+J12 -> 85553.441 | ... M13: =M10+M12 -> 103491.78
B14: EBIT Margin % | C14: =C13/C7 -> 0.306 | D14: =D13/D7 -> 0.28044947 | E14: =E13/E7 -> 0.30169209 | F14: =F13/F7 -> 0.30055123 | G14: =G13/G7 -> 0.30549583 | H14: =H13/H7 -> 0.31181816 | I14: =I13/I7 -> 0.322194 | J14: =J13/J7 -> 0.33065443 | ... M14: =M13/M7 -> 0.34364413
B15: Less: Cash Taxes on EBIT | C15: =-C13*'Assumptions & WACC'!$C$21 -> -3918.636 | D15: =-D13*'Assumptions & WACC'!$C$21 -> -4762.244 | E15: =-E13*'Assumptions & WACC'!$C$21 -> -7494.8902 | F15: =-F13*'Assumptions & WACC'!$C$21 -> -9333.185 | G15: =-G13*'Assumptions & WACC'!$C$21 -> -11194.344 | H15: =-H13*'Assumptions & WACC'!$C$21 -> -12797.136 | I15: =-I13*'Assumptions & WACC'!$C$21 -> -14584.93 | J15: =-J13*'Assumptions & WACC'!$C$21 -> -16255.154 | ... M15: =-M13*'Assumptions & WACC'!$C$21 -> -19663.438
B16: NOPAT | C16: =C13+C15 -> 16705.764 | D16: =D13+D15 -> 20302.198 | E16: =E13+E15 -> 31951.9 | F16: =F13+F15 -> 39788.841 | G16: =G13+G15 -> 47723.257 | H16: =H13+H15 -> 54556.212 | I16: =I13+I15 -> 62177.859 | J16: =J13+J15 -> 69298.287 | ... M16: =M13+M15 -> 83828.341
B17: Add: D&A | C17: =-C12 -> 9705.6 | D17: =-D12 -> 15600 | E17: =-E12 -> 20699.047 | F17: =-F12 -> 26060.271 | G17: =-G12 -> 29797.509 | H17: =-H12 -> 32007.576 | I17: =-I12 -> 32832.31 | J17: =-J12 -> 33466.837 | ... M17: =-M12 -> 35041.704
B18: Less: Capex | C18: =-C7*'Assumptions & WACC'!C41 -> -55672.4 | D18: =-D7*'Assumptions & WACC'!D41 -> -58092.06 | E18: =-E7*'Assumptions & WACC'!E41 -> -65375.911 | F18: =-F7*'Assumptions & WACC'!F41 -> -57203.922 | G18: =-G7*'Assumptions & WACC'!G41 -> -48214.734 | H18: =-H7*'Assumptions & WACC'!H41 -> -38880.362 | I18: =-I7*'Assumptions & WACC'!I41 -> -38120.034 | J18: =-J7*'Assumptions & WACC'!J41 -> -38810.96 | ... M18: =-M7*'Assumptions & WACC'!M41 -> -37644.968
B19: Less: Increase in NWC | C19: n/a | D19: =-(D7-C7)*'Assumptions & WACC'!$C$32 -> -659.172 | E19: =-(E7-D7)*'Assumptions & WACC'!$C$32 -> -1241.3826 | F19: =-(F7-E7)*'Assumptions & WACC'!$C$32 -> -980.63866 | G19: =-(G7-F7)*'Assumptions & WACC'!$C$32 -> -882.57479 | H19: =-(H7-G7)*'Assumptions & WACC'!$C$32 -> -694.29217 | I19: =-(I7-H7)*'Assumptions & WACC'!$C$32 -> -667.44621 | J19: =-(J7-I7)*'Assumptions & WACC'!$C$32 -> -614.68556 | K19: =-(K7-J7)*'Assumptions & WACC'!$C$32 -> -535.59125 | ... M19: =-(M7-L7)*'Assumptions & WACC'!$C$32 -> -305.52438
B20: Unlevered Free Cash Flow | C20: n/a | D20: =D16+D17+D18+D19 -> -22849.034 | E20: =E16+E17+E18+E19 -> -13966.346 | F20: =F16+F17+F18+F19 -> 7664.5517 | G20: =G16+G17+G18+G19 -> 28423.457 | H20: =H16+H17+H18+H19 -> 46989.134 | I20: =I16+I17+I18+I19 -> 56222.689 | J20: =J16+J17+J18+J19 -> 63339.478 | K20: =K16+K17+K18+K19 -> 70280.433 | ... M20: =M16+M17+M18+M19 -> 80919.553
B22: NET PP&E ROLL-FORWARD (drives D&A)
B23: Beginning Net PP&E | C23: n/a | D23: =C26 -> 130000 | E23: =D26 -> 172492.06 | F23: =E26 -> 217168.92 | G23: =F26 -> 248312.57 | H23: =G26 -> 266729.8 | I23: =H26 -> 273602.59 | J23: =I26 -> 278890.31 | K23: =J26 -> 284234.43 | ... M23: =L26 -> 292014.2
B24: Add: Capex | C24: n/a | D24: =-D18 -> 58092.06 | E24: =-E18 -> 65375.911 | F24: =-F18 -> 57203.922 | G24: =-G18 -> 48214.734 | H24: =-H18 -> 38880.362 | I24: =-I18 -> 38120.034 | J24: =-J18 -> 38810.96 | K24: =-K18 -> 38722.989 | ... M24: =-M18 -> 37644.968
B25: Less: D&A | C25: n/a | D25: =D12 -> -15600 | E25: =E12 -> -20699.047 | F25: =F12 -> -26060.271 | G25: =G12 -> -29797.509 | H25: =H12 -> -32007.576 | I25: =I12 -> -32832.31 | J25: =J12 -> -33466.837 | K25: =K12 -> -34108.132 | ... M25: =M12 -> -35041.704
B26: Ending Net PP&E | C26: ='Assumptions & WACC'!$C$33 -> 130000 | D26: =D23+D24+D25 -> 172492.06 | E26: =E23+E24+E25 -> 217168.92 | F26: =F23+F24+F25 -> 248312.57 | G26: =G23+G24+G25 -> 266729.8 | H26: =H23+H24+H25 -> 273602.59 | I26: =I23+I24+I25 -> 278890.31 | J26: =J23+J24+J25 -> 284234.43 | K26: =K23+K24+K25 -> 288849.29 | ... M26: =M23+M24+M25 -> 294617.47
B27: Capex / D&A (x) | C27: =IF(C12=0,0,C18/C12) -> 5.7361111 | D27: =IF(D12=0,0,D18/D12) -> 3.72385 | E27: =IF(E12=0,0,E18/E12) -> 3.1584019 | F27: =IF(F12=0,0,F18/F12) -> 2.1950624 | G27: =IF(G12=0,0,G18/G12) -> 1.6180794 | H27: =IF(H12=0,0,H18/H12) -> 1.2147237 | I27: =IF(I12=0,0,I18/I12) -> 1.1610525 | J27: =IF(J12=0,0,J18/J12) -> 1.1596841 | ... M27: =IF(M12=0,0,M18/M12) -> 1.0742904
B29: DISCOUNTING
B30: Year | C30: n/a | D30: 1 | E30: =D30+1 -> 2 | F30: =E30+1 -> 3 | G30: =F30+1 -> 4 | H30: =G30+1 -> 5 | I30: =H30+1 -> 6 | J30: =I30+1 -> 7 | K30: =J30+1 -> 8 | L30: =K30+1 -> 9 | M30: =L30+1 -> 10
B31: Discount Period (mid-year adjusted) | C31: n/a | D31: =D30-0.5*'Assumptions & WACC'!$C$30 -> 0.5 | E31: =E30-0.5*'Assumptions & WACC'!$C$30 -> 1.5 | F31: =F30-0.5*'Assumptions & WACC'!$C$30 -> 2.5 | G31: =G30-0.5*'Assumptions & WACC'!$C$30 -> 3.5 | H31: =H30-0.5*'Assumptions & WACC'!$C$30 -> 4.5 | I31: =I30-0.5*'Assumptions & WACC'!$C$30 -> 5.5 | J31: =J30-0.5*'Assumptions & WACC'!$C$30 -> 6.5 | K31: =K30-0.5*'Assumptions & WACC'!$C$30 -> 7.5 | ... M31: =M30-0.5*'Assumptions & WACC'!$C$30 -> 9.5
B32: Discount Factor | C32: n/a | D32: =1/(1+'Assumptions & WACC'!$C$25)^D31 -> 0.95037027 | E32: =1/(1+'Assumptions & WACC'!$C$25)^E31 -> 0.85837788 | F32: =1/(1+'Assumptions & WACC'!$C$25)^F31 -> 0.77529003 | G32: =1/(1+'Assumptions & WACC'!$C$25)^G31 -> 0.70024478 | H32: =1/(1+'Assumptions & WACC'!$C$25)^H31 -> 0.63246363 | I32: =1/(1+'Assumptions & WACC'!$C$25)^I31 -> 0.57124346 | J32: =1/(1+'Assumptions & WACC'!$C$25)^J31 -> 0.51594917 | K32: =1/(1+'Assumptions & WACC'!$C$25)^K31 -> 0.46600717 | ... M32: =1/(1+'Assumptions & WACC'!$C$25)^M31 -> 0.38015785
B33: PV of Unlevered FCF | C33: n/a | D33: =D20*D32 -> -21715.042 | E33: =E20*E32 -> -11988.402 | F33: =F20*F32 -> 5942.2506 | G33: =G20*G32 -> 19903.378 | H33: =H20*H32 -> 29718.919 | I33: =I20*I32 -> 32116.843 | J33: =J20*J32 -> 32679.951 | K33: =K20*K32 -> 32751.186 | ... M33: =M20*M32 -> 30762.203
B35: ENTERPRISE & EQUITY VALUE
B36: Sum of PV of Explicit FCFs (FY27-FY36) | D36: =SUM(D33:M33) -> 182473.19
B37: Terminal Value (end FY2036, Gordon Growth) | D37: =M20*(1+'Assumptions & WACC'!$C$31)/('Assumptions & WACC'!$C$25-'Assumptions & WACC'!$C$31) -> 1160478.1
B38: PV of Terminal Value | D38: =D37*M32 -> 441164.86
B39: Enterprise Value | D39: =D36+D38 -> 623638.05
B40: Less: Net Debt (incl. leases) | D40: =-'Assumptions & WACC'!$C$13 -> -98252
B41: Implied Equity Value | D41: =D39+D40 -> 525386.05
B42: ÷ Diluted Shares Outstanding (mm) | D42: ='Assumptions & WACC'!$C$7 -> 2880
B43: Implied Share Price | D43: =D41/D42 -> 182.42571
B44: Current Share Price | D44: ='Assumptions & WACC'!$C$6 -> 142.48
B45: Implied Upside / (Downside) | D45: =D43/D44-1 -> 0.28036013
B47: SANITY CHECKS
...

Sheet Sensitivity
B2: Sensitivity: Implied Share Price
B3: Each cell independently re-runs the 10-year DCF (active scenario, mid-year setting) at the row/column inputs.
C5: Table 1 — WACC vs. Terminal Growth
C6: WACC \ Term. g | D6: ='Assumptions & WACC'!$C$31+(-0.01) -> 0.025 | E6: ='Assumptions & WACC'!$C$31+(-0.005) -> 0.03 | F6: ='Assumptions & WACC'!$C$31+(0) -> 0.035 | G6: ='Assumptions & WACC'!$C$31+(0.005) -> 0.04 | H6: ='Assumptions & WACC'!$C$31+(0.01) -> 0.045
C7: ='Assumptions & WACC'!$C$25+(-0.01) -> 0.097170027 | D7: =(SUMPRODUCT('DCF Valuation'!$D$20:$M$20,1/(1+$C7)^'DCF Valuation'!$D$31:$M$31)+('DCF Valuation'!$M$20*(1+D$6)/($C7-D$6))/(1+$C7)^'DCF Valuation'!$M$31-'Assumptions & WACC'!$C$13)/'Assumptions & WACC'!$C$7 -> 199.13208 | E7: =(SUMPRODUCT('DCF Valuation'!$D$20:$M$20,1/(1+$C7)^'DCF Valuation'!$D$31:$M$31)+('DCF Valuation'!$M$20*(1+E$6)/($C7-E$6))/(1+$C7)^'DCF Valuation'!$M$31-'Assumptions & WACC'!$C$13)/'Assumptions & WACC'!$C$7 -> 212.30768 | F7: =(SUMPRODUCT('DCF Valuation'!$D$20:$M$20,1/(1+$C7)^'DCF Valuation'!$D$31:$M$31)+('DCF Valuation'!$M$20*(1+F$6)/($C7-F$6))/(1+$C7)^'DCF Valuation'!$M$31-'Assumptions & WACC'!$C$13)/'Assumptions & WACC'!$C$7 -> 227.60255 | G7: =(SUMPRODUCT('DCF Valuation'!$D$20:$M$20,1/(1+$C7)^'DCF Valuation'!$D$31:$M$31)+('DCF Valuation'!$M$20*(1+G$6)/($C7-G$6))/(1+$C7)^'DCF Valuation'!$M$31-'Assumptions & WACC'!$C$13)/'Assumptions & WACC'!$C$7 -> 245.57276 | H7: =(SUMPRODUCT('DCF Valuation'!$D$20:$M$20,1/(1+$C7)^'DCF Valuation'!$D$31:$M$31)+('DCF Valuation'!$M$20*(1+H$6)/($C7-H$6))/(1+$C7)^'DCF Valuation'!$M$31-'Assumptions & WACC'!$C$13)/'Assumptions & WACC'!$C$7 -> 266.98751
C8: ='Assumptions & WACC'!$C$25+(-0.005) -> 0.10217003 | D8: =(SUMPRODUCT('DCF Valuation'!$D$20:$M$20,1/(1+$C8)^'DCF Valuation'!$D$31:$M$31)+('DCF Valuation'!$M$20*(1+D$6)/($C8-D$6))/(1+$C8)^'DCF Valuation'!$M$31-'Assumptions & WACC'!$C$13)/'Assumptions & WACC'!$C$7 -> 179.57263 | E8: =(SUMPRODUCT('DCF Valuation'!$D$20:$M$20,1/(1+$C8)^'DCF Valuation'!$D$31:$M$31)+('DCF Valuation'!$M$20*(1+E$6)/($C8-E$6))/(1+$C8)^'DCF Valuation'!$M$31-'Assumptions & WACC'!$C$13)/'Assumptions & WACC'!$C$7 -> 190.60611 | F8: =(SUMPRODUCT('DCF Valuation'!$D$20:$M$20,1/(1+$C8)^'DCF Valuation'!$D$31:$M$31)+('DCF Valuation'!$M$20*(1+F$6)/($C8-F$6))/(1+$C8)^'DCF Valuation'!$M$31-'Assumptions & WACC'!$C$13)/'Assumptions & WACC'!$C$7 -> 203.28221 | G8: =(SUMPRODUCT('DCF Valuation'!$D$20:$M$20,1/(1+$C8)^'DCF Valuation'!$D$31:$M$31)+('DCF Valuation'!$M$20*(1+G$6)/($C8-G$6))/(1+$C8)^'DCF Valuation'!$M$31-'Assumptions & WACC'!$C$13)/'Assumptions & WACC'!$C$7 -> 217.99724 | H8: =(SUMPRODUCT('DCF Valuation'!$D$20:$M$20,1/(1+$C8)^'DCF Valuation'!$D$31:$M$31)+('DCF Valuation'!$M$20*(1+H$6)/($C8-H$6))/(1+$C8)^'DCF Valuation'!$M$31-'Assumptions & WACC'!$C$13)/'Assumptions & WACC'!$C$7 -> 235.28619
C9: ='Assumptions & WACC'!$C$25+(0) -> 0.10717003 | D9: =(SUMPRODUCT('DCF Valuation'!$D$20:$M$20,1/(1+$C9)^'DCF Valuation'!$D$31:$M$31)+('DCF Valuation'!$M$20*(1+D$6)/($C9-D$6))/(1+$C9)^'DCF Valuation'!$M$31-'Assumptions & WACC'!$C$13)/'Assumptions & WACC'!$C$7 -> 162.4837 | E9: =(SUMPRODUCT('DCF Valuation'!$D$20:$M$20,1/(1+$C9)^'DCF Valuation'!$D$31:$M$31)+('DCF Valuation'!$M$20*(1+E$6)/($C9-E$6))/(1+$C9)^'DCF Valuation'!$M$31-'Assumptions & WACC'!$C$13)/'Assumptions & WACC'!$C$7 -> 171.80866 | F9: =(SUMPRODUCT('DCF Valuation'!$D$20:$M$20,1/(1+$C9)^'DCF Valuation'!$D$31:$M$31)+('DCF Valuation'!$M$20*(1+F$6)/($C9-F$6))/(1+$C9)^'DCF Valuation'!$M$31-'Assumptions & WACC'!$C$13)/'Assumptions & WACC'!$C$7 -> 182.42571 | G9: =(SUMPRODUCT('DCF Valuation'!$D$20:$M$20,1/(1+$C9)^'DCF Valuation'!$D$31:$M$31)+('DCF Valuation'!$M$20*(1+G$6)/($C9-G$6))/(1+$C9)^'DCF Valuation'!$M$31-'Assumptions & WACC'!$C$13)/'Assumptions & WACC'!$C$7 -> 194.62338 | H9: =(SUMPRODUCT('DCF Valuation'!$D$20:$M$20,1/(1+$C9)^'DCF Valuation'!$D$31:$M$31)+('DCF Valuation'!$M$20*(1+H$6)/($C9-H$6))/(1+$C9)^'DCF Valuation'!$M$31-'Assumptions & WACC'!$C$13)/'Assumptions & WACC'!$C$7 -> 208.78304
C10: ='Assumptions & WACC'!$C$25+(0.005) -> 0.11217003 | D10: =(SUMPRODUCT('DCF Valuation'!$D$20:$M$20,1/(1+$C10)^'DCF Valuation'!$D$31:$M$31)+('DCF Valuation'!$M$20*(1+D$6)/($C10-D$6))/(1+$C10)^'DCF Valuation'!$M$31-'Assumptions & WACC'!$C$13)/'Assumptions & WACC'!$C$7 -> 147.43756 | E10: =(SUMPRODUCT('DCF Valuation'!$D$20:$M$20,1/(1+$C10)^'DCF Valuation'!$D$31:$M$31)+('DCF Valuation'!$M$20*(1+E$6)/($C10-E$6))/(1+$C10)^'DCF Valuation'!$M$31-'Assumptions & WACC'!$C$13)/'Assumptions & WACC'!$C$7 -> 155.38259 | F10: =(SUMPRODUCT('DCF Valuation'!$D$20:$M$20,1/(1+$C10)^'DCF Valuation'!$D$31:$M$31)+('DCF Valuation'!$M$20*(1+F$6)/($C10-F$6))/(1+$C10)^'DCF Valuation'!$M$31-'Assumptions & WACC'!$C$13)/'Assumptions & WACC'!$C$7 -> 164.35716 | G10: =(SUMPRODUCT('DCF Valuation'!$D$20:$M$20,1/(1+$C10)^'DCF Valuation'!$D$31:$M$31)+('DCF Valuation'!$M$20*(1+G$6)/($C10-G$6))/(1+$C10)^'DCF Valuation'!$M$31-'Assumptions & WACC'!$C$13)/'Assumptions & WACC'!$C$7 -> 174.57527 | H10: =(SUMPRODUCT('DCF Valuation'!$D$20:$M$20,1/(1+$C10)^'DCF Valuation'!$D$31:$M$31)+('DCF Valuation'!$M$20*(1+H$6)/($C10-H$6))/(1+$C10)^'DCF Valuation'!$M$31-'Assumptions & WACC'!$C$13)/'Assumptions & WACC'!$C$7 -> 186.3146
C11: ='Assumptions & WACC'!$C$25+(0.01) -> 0.11717003 | D11: =(SUMPRODUCT('DCF Valuation'!$D$20:$M$20,1/(1+$C11)^'DCF Valuation'!$D$31:$M$31)+('DCF Valuation'!$M$20*(1+D$6)/($C11-D$6))/(1+$C11)^'DCF Valuation'!$M$31-'Assumptions & WACC'!$C$13)/'Assumptions & WACC'!$C$7 -> 134.09941 | E11: =(SUMPRODUCT('DCF Valuation'!$D$20:$M$20,1/(1+$C11)^'DCF Valuation'!$D$31:$M$31)+('DCF Valuation'!$M$20*(1+E$6)/($C11-E$6))/(1+$C11)^'DCF Valuation'!$M$31-'Assumptions & WACC'!$C$13)/'Assumptions & WACC'!$C$7 -> 140.91746 | F11: =(SUMPRODUCT('DCF Valuation'!$D$20:$M$20,1/(1+$C11)^'DCF Valuation'!$D$31:$M$31)+('DCF Valuation'!$M$20*(1+F$6)/($C11-F$6))/(1+$C11)^'DCF Valuation'!$M$31-'Assumptions & WACC'!$C$13)/'Assumptions & WACC'!$C$7 -> 148.56526 | G11: =(SUMPRODUCT('DCF Valuation'!$D$20:$M$20,1/(1+$C11)^'DCF Valuation'!$D$31:$M$31)+('DCF Valuation'!$M$20*(1+G$6)/($C11-G$6))/(1+$C11)^'DCF Valuation'!$M$31-'Assumptions & WACC'!$C$13)/'Assumptions & WACC'!$C$7 -> 157.20409 | H11: =(SUMPRODUCT('DCF Valuation'!$D$20:$M$20,1/(1+$C11)^'DCF Valuation'!$D$31:$M$31)+('DCF Valuation'!$M$20*(1+H$6)/($C11-H$6))/(1+$C11)^'DCF Valuation'!$M$31-'Assumptions & WACC'!$C$13)/'Assumptions & WACC'!$C$7 -> 167.03994
C12: Center (highlighted) cell = base WACC and terminal growth; it ties to the Implied Share Price on the DCF tab.
C15: Table 2 — Levered Beta vs. Terminal Growth (WACC recomputed for each beta)
C16: Beta | D16: Implied WACC | E16: ='Assumptions & WACC'!$C$31+(-0.01) -> 0.025 | F16: ='Assumptions & WACC'!$C$31+(-0.005) -> 0.03 | G16: ='Assumptions & WACC'!$C$31+(0) -> 0.035 | H16: ='Assumptions & WACC'!$C$31+(0.005) -> 0.04 | I16: ='Assumptions & WACC'!$C$31+(0.01) -> 0.045
C17: 1 | D17: ='Assumptions & WACC'!$C$23*('Assumptions & WACC'!$C$16+C17*'Assumptions & WACC'!$C$17)+'Assumptions & WACC'!$C$24*'Assumptions & WACC'!$C$22 -> 0.083866666 | E17: =(SUMPRODUCT('DCF Valuation'!$D$20:$M$20,1/(1+$D17)^'DCF Valuation'!$D$31:$M$31)+('DCF Valuation'!$M$20*(1+E$16)/($D17-E$16))/(1+$D17)^'DCF Valuation'!$M$31-'Assumptions & WACC'!$C$13)/'Assumptions & WACC'!$C$7 -> 267.99822 | F17: =(SUMPRODUCT('DCF Valuation'!$D$20:$M$20,1/(1+$D17)^'DCF Valuation'!$D$31:$M$31)+('DCF Valuation'!$M$20*(1+F$16)/($D17-F$16))/(1+$D17)^'DCF Valuation'!$M$31-'Assumptions & WACC'!$C$13)/'Assumptions & WACC'!$C$7 -> 290.34149 | G17: =(SUMPRODUCT('DCF Valuation'!$D$20:$M$20,1/(1+$D17)^'DCF Valuation'!$D$31:$M$31)+('DCF Valuation'!$M$20*(1+G$16)/($D17-G$16))/(1+$D17)^'DCF Valuation'!$M$31-'Assumptions & WACC'!$C$13)/'Assumptions & WACC'!$C$7 -> 317.25704 | H17: =(SUMPRODUCT('DCF Valuation'!$D$20:$M$20,1/(1+$D17)^'DCF Valuation'!$D$31:$M$31)+('DCF Valuation'!$M$20*(1+H$16)/($D17-H$16))/(1+$D17)^'DCF Valuation'!$M$31-'Assumptions & WACC'!$C$13)/'Assumptions & WACC'!$C$7 -> 350.30837 | I17: =(SUMPRODUCT('DCF Valuation'!$D$20:$M$20,1/(1+$D17)^'DCF Valuation'!$D$31:$M$31)+('DCF Valuation'!$M$20*(1+I$16)/($D17-I$16))/(1+$D17)^'DCF Valuation'!$M$31-'Assumptions & WACC'!$C$13)/'Assumptions & WACC'!$C$7 -> 391.86346
C18: 1.2 | D18: ='Assumptions & WACC'!$C$23*('Assumptions & WACC'!$C$16+C18*'Assumptions & WACC'!$C$17)+'Assumptions & WACC'!$C$24*'Assumptions & WACC'!$C$22 -> 0.090251148 | E18: =(SUMPRODUCT('DCF Valuation'!$D$20:$M$20,1/(1+$D18)^'DCF Valuation'!$D$31:$M$31)+('DCF Valuation'!$M$20*(1+E$16)/($D18-E$16))/(1+$D18)^'DCF Valuation'!$M$31-'Assumptions & WACC'!$C$13)/'Assumptions & WACC'!$C$7 -> 231.33588 | F18: =(SUMPRODUCT('DCF Valuation'!$D$20:$M$20,1/(1+$D18)^'DCF Valuation'!$D$31:$M$31)+('DCF Valuation'!$M$20*(1+F$16)/($D18-F$16))/(1+$D18)^'DCF Valuation'!$M$31-'Assumptions & WACC'!$C$13)/'Assumptions & WACC'!$C$7 -> 248.47947 | G18: =(SUMPRODUCT('DCF Valuation'!$D$20:$M$20,1/(1+$D18)^'DCF Valuation'!$D$31:$M$31)+('DCF Valuation'!$M$20*(1+G$16)/($D18-G$16))/(1+$D18)^'DCF Valuation'!$M$31-'Assumptions & WACC'!$C$13)/'Assumptions & WACC'!$C$7 -> 268.72591 | H18: =(SUMPRODUCT('DCF Valuation'!$D$20:$M$20,1/(1+$D18)^'DCF Valuation'!$D$31:$M$31)+('DCF Valuation'!$M$20*(1+H$16)/($D18-H$16))/(1+$D18)^'DCF Valuation'!$M$31-'Assumptions & WACC'!$C$13)/'Assumptions & WACC'!$C$7 -> 293.0014 | I18: =(SUMPRODUCT('DCF Valuation'!$D$20:$M$20,1/(1+$D18)^'DCF Valuation'!$D$31:$M$31)+('DCF Valuation'!$M$20*(1+I$16)/($D18-I$16))/(1+$D18)^'DCF Valuation'!$M$31-'Assumptions & WACC'!$C$13)/'Assumptions & WACC'!$C$7 -> 322.64151
C19: 1.4 | D19: ='Assumptions & WACC'!$C$23*('Assumptions & WACC'!$C$16+C19*'Assumptions & WACC'!$C$17)+'Assumptions & WACC'!$C$24*'Assumptions & WACC'!$C$22 -> 0.096635631 | E19: =(SUMPRODUCT('DCF Valuation'!$D$20:$M$20,1/(1+$D19)^'DCF Valuation'!$D$31:$M$31)+('DCF Valuation'!$M$20*(1+E$16)/($D19-E$16))/(1+$D19)^'DCF Valuation'!$M$31-'Assumptions & WACC'!$C$13)/'Assumptions & WACC'!$C$7 -> 201.39034 | F19: =(SUMPRODUCT('DCF Valuation'!$D$20:$M$20,1/(1+$D19)^'DCF Valuation'!$D$31:$M$31)+('DCF Valuation'!$M$20*(1+F$16)/($D19-F$16))/(1+$D19)^'DCF Valuation'!$M$31-'Assumptions & WACC'!$C$13)/'Assumptions & WACC'!$C$7 -> 214.8262 | G19: =(SUMPRODUCT('DCF Valuation'!$D$20:$M$20,1/(1+$D19)^'DCF Valuation'!$D$31:$M$31)+('DCF Valuation'!$M$20*(1+G$16)/($D19-G$16))/(1+$D19)^'DCF Valuation'!$M$31-'Assumptions & WACC'!$C$13)/'Assumptions & WACC'!$C$7 -> 230.44194 | H19: =(SUMPRODUCT('DCF Valuation'!$D$20:$M$20,1/(1+$D19)^'DCF Valuation'!$D$31:$M$31)+('DCF Valuation'!$M$20*(1+H$16)/($D19-H$16))/(1+$D19)^'DCF Valuation'!$M$31-'Assumptions & WACC'!$C$13)/'Assumptions & WACC'!$C$7 -> 248.81492 | I19: =(SUMPRODUCT('DCF Valuation'!$D$20:$M$20,1/(1+$D19)^'DCF Valuation'!$D$31:$M$31)+('DCF Valuation'!$M$20*(1+I$16)/($D19-I$16))/(1+$D19)^'DCF Valuation'!$M$31-'Assumptions & WACC'!$C$13)/'Assumptions & WACC'!$C$7 -> 270.74608
C20: 1.6 | D20: ='Assumptions & WACC'!$C$23*('Assumptions & WACC'!$C$16+C20*'Assumptions & WACC'!$C$17)+'Assumptions & WACC'!$C$24*'Assumptions & WACC'!$C$22 -> 0.10302011 | E20: =(SUMPRODUCT('DCF Valuation'!$D$20:$M$20,1/(1+$D20)^'DCF Valuation'!$D$31:$M$31)+('DCF Valuation'!$M$20*(1+E$16)/($D20-E$16))/(1+$D20)^'DCF Valuation'!$M$31-'Assumptions & WACC'!$C$13)/'Assumptions & WACC'!$C$7 -> 176.50606 | F20: =(SUMPRODUCT('DCF Valuation'!$D$20:$M$20,1/(1+$D20)^'DCF Valuation'!$D$31:$M$31)+('DCF Valuation'!$M$20*(1+F$16)/($D20-F$16))/(1+$D20)^'DCF Valuation'!$M$31-'Assumptions & WACC'!$C$13)/'Assumptions & WACC'!$C$7 -> 187.22182 | G20: =(SUMPRODUCT('DCF Valuation'!$D$20:$M$20,1/(1+$D20)^'DCF Valuation'!$D$31:$M$31)+('DCF Valuation'!$M$20*(1+G$16)/($D20-G$16))/(1+$D20)^'DCF Valuation'!$M$31-'Assumptions & WACC'!$C$13)/'Assumptions & WACC'!$C$7 -> 199.51295 | H20: =(SUMPRODUCT('DCF Valuation'!$D$20:$M$20,1/(1+$D20)^'DCF Valuation'!$D$31:$M$31)+('DCF Valuation'!$M$20*(1+H$16)/($D20-H$16))/(1+$D20)^'DCF Valuation'!$M$31-'Assumptions & WACC'!$C$13)/'Assumptions & WACC'!$C$7 -> 213.75443 | I20: =(SUMPRODUCT('DCF Valuation'!$D$20:$M$20,1/(1+$D20)^'DCF Valuation'!$D$31:$M$31)+('DCF Valuation'!$M$20*(1+I$16)/($D20-I$16))/(1+$D20)^'DCF Valuation'!$M$31-'Assumptions & WACC'!$C$13)/'Assumptions & WACC'!$C$7 -> 230.4505
C21: ='Assumptions & WACC'!$C$18 -> 1.73 | D21: ='Assumptions & WACC'!$C$23*('Assumptions & WACC'!$C$16+C21*'Assumptions & WACC'!$C$17)+'Assumptions & WACC'!$C$24*'Assumptions & WACC'!$C$22 -> 0.10717003 | E21: =(SUMPRODUCT('DCF Valuation'!$D$20:$M$20,1/(1+$D21)^'DCF Valuation'!$D$31:$M$31)+('DCF Valuation'!$M$20*(1+E$16)/($D21-E$16))/(1+$D21)^'DCF Valuation'!$M$31-'Assumptions & WACC'!$C$13)/'Assumptions & WACC'!$C$7 -> 162.4837 | F21: =(SUMPRODUCT('DCF Valuation'!$D$20:$M$20,1/(1+$D21)^'DCF Valuation'!$D$31:$M$31)+('DCF Valuation'!$M$20*(1+F$16)/($D21-F$16))/(1+$D21)^'DCF Valuation'!$M$31-'Assumptions & WACC'!$C$13)/'Assumptions & WACC'!$C$7 -> 171.80866 | G21: =(SUMPRODUCT('DCF Valuation'!$D$20:$M$20,1/(1+$D21)^'DCF Valuation'!$D$31:$M$31)+('DCF Valuation'!$M$20*(1+G$16)/($D21-G$16))/(1+$D21)^'DCF Valuation'!$M$31-'Assumptions & WACC'!$C$13)/'Assumptions & WACC'!$C$7 -> 182.42571 | H21: =(SUMPRODUCT('DCF Valuation'!$D$20:$M$20,1/(1+$D21)^'DCF Valuation'!$D$31:$M$31)+('DCF Valuation'!$M$20*(1+H$16)/($D21-H$16))/(1+$D21)^'DCF Valuation'!$M$31-'Assumptions & WACC'!$C$13)/'Assumptions & WACC'!$C$7 -> 194.62338 | I21: =(SUMPRODUCT('DCF Valuation'!$D$20:$M$20,1/(1+$D21)^'DCF Valuation'!$D$31:$M$31)+('DCF Valuation'!$M$20*(1+I$16)/($D21-I$16))/(1+$D21)^'DCF Valuation'!$M$31-'Assumptions & WACC'!$C$13)/'Assumptions & WACC'!$C$7 -> 208.78304
C22: Last row = beta currently on the Assumptions tab (its center cell matches Table 1). Rows above are illustrative betas spanning the 2026 vendor range (~1.26-1.72) and below.
